<?xml version="1.0" ?>
<mujoco model="d1_description">
    <actuator>
        <motor ctrllimited="true" ctrlrange="-3.3 3.3" joint="joint1" name="torq_j1"/>
        <motor ctrllimited="true" ctrlrange="-3.3 3.3" joint="joint2" name="torq_j2"/>
        <motor ctrllimited="true" ctrlrange="-1.7 1.7" joint="joint3" name="torq_j3"/>
        <motor ctrllimited="true" ctrlrange="-1.7 1.7" joint="joint4" name="torq_j4"/>
        <motor ctrllimited="true" ctrlrange="-1.7 1.7" joint="joint5" name="torq_j5"/>
        <motor ctrllimited="true" ctrlrange="-1.7 1.7" joint="joint6" name="torq_j6"/>
    </actuator>
    <asset>
        <mesh file="meshes/base_link.STL" name="base_link"/>
        <mesh file="meshes/Link1.STL" name="link1"/>
        <mesh file="meshes/Link2.STL" name="link2"/>
        <mesh file="meshes/Link3.STL" name="link3"/>
        <mesh file="meshes/Link4.STL" name="link4"/>
        <mesh file="meshes/Link5.STL" name="link5"/>
        <mesh file="meshes/Link6.STL" name="link6"/>
        <mesh file="meshes/Link7_1.STL" name="link7_1"/>
        <mesh file="meshes/Link7_2.STL" name="link7_2"/>
    </asset>
    <worldbody>
        <body name="base" pos="0 0 0">
            <!-- robot view -->
            <camera mode="fixed" name="robotview" pos="1.0 0 0.4" quat="0.653 0.271 0.271 0.653"/>
            <inertial diaginertia="0 0 0" mass="0" pos="0 0 0"/>
            <!-- mount attached here -->
            <!-- Base link -->
            <body name="base_link" pos="0 0 0">
                <site name="right_center" pos="0 0 0" size="0.01" rgba="1 0.3 0.3 1" group="2"/>
                <inertial pos="-0.00048697 -2.9605E-12 0.017142" mass="0.077233"
                          fullinertia="0.00010316 0.00011888 0.00018362 -1.0285E-14 2.0449E-07 7.3026E-15"/>
                <geom name="base_link_visual" class="visual" mesh="base_link" rgba="1 1 1 1" group="1"/>
                <geom name="base_link_collision" class="collision" mesh="base_link"/>
                <!-- Link 1 with corrected transformation -->
                <body name="link1" pos="0 0 0.0533" euler="0 0 3.1416">
                    <!-- Optionally, an alternate inertial is commented out -->
                    <!-- <inertial pos="0.0024649 0.00010517 0.032696" mass="0.13174"
                          fullinertia="6.7236E-05 5.416E-05 4.6637E-05 -5.5664E-08 7.0454E-08 -3.5709E-07"/> -->
                    <inertial pos="0.0024649 -0.10517 0.032696" mass="0.13174"
                          fullinertia="6.7236E-05 5.416E-05 4.6637E-05 -5.5664E-08 7.0454E-08 -3.5709E-07"/>
                    <joint name="joint1" type="hinge" axis="0 0 1" pos="0 0 0"
                           range="-2.35 2.35"/>
                    <geom name="link1_visual" class="visual" mesh="link1" rgba="1 1 1 1" group="1"/>
                    <geom name="link1_collision" class="collision" mesh="link1"/>
                    <!-- Link 2 with corrected transformation -->
                    <!-- <body name="link2" pos="0 0.028 0.0563" euler="1.5708 0 0"> -->
                    <body name="link2" pos="0 0.028 0.0563" euler="-1.5708 0 3.14">
                        <inertial pos="0.0002018 0.19201 -0.027007" mass="0.20213"
                                  fullinertia="0.00025682 6.3307E-05 0.00022968 -1.139E-07 5.5667E-08 -3.5717E-07"/>
                        <joint name="joint2" type="hinge" axis="0 0 -1" pos="0 0 0"
                               range="-1.57 1.57"/>
                        <geom name="link2_visual" class="visual" mesh="link2" rgba="1 1 1 1" group="1"/>
                        <geom name="link2_collision" class="collision" mesh="link2"/>
                        <body name="link3" pos="0 0.2693 0.0009">
                            <inertial pos="0.015164 0.044482 -0.027461" mass="0.0629"
                                      fullinertia="1.7232E-05 1.2606E-05 1.4964E-05 -2.6967E-06 -9.4911E-11 -9.9169E-11"/>
                            <joint name="joint3" type="hinge" axis="0 0 -1" pos="0 0 0"
                                   range="-1.57 1.57"/>
                            <geom name="link3_visual" class="visual" mesh="link3" rgba="1 1 1 1" group="1"/>
                            <geom name="link3_collision" class="collision" mesh="link3"/>
                            <!-- <body name="link4" pos="0.0577 0.042 -0.0275" euler="-1.5708 0 -1.5708"> -->
                            <body name="link4" pos="0.0577 0.042 -0.0275" euler="0 1.5708 -1.5708">
                                <inertial pos="-0.00029556 -0.00016104 0.091339" mass="0.083332"
                                          fullinertia="3.9308E-05 3.4378E-05 1.1597E-05 1.0126E-08 -9.4316E-08 -1.6915E-09"/>
                                <joint name="joint4" type="hinge" axis="0 0 1" pos="0 0 0"
                                       range="-2.35 2.35"/>
                                <geom name="link4_visual" class="visual" mesh="link4" rgba="1 1 1 1" group="1"/>
                                <geom name="link4_collision" class="collision" mesh="link4"/>
                                <body name="link5" pos="-0.0001 -0.0237 0.14018" euler="1.5708 0 1.5708">
                                    <inertial pos="0.040573 0.0062891 -0.023838" mass="0.053817"
                                              fullinertia="1.3072E-05 8.6301E-06 1.1049E-05 -3.9511E-07 -3.1889E-10 -1.8416E-09"/>
                                    <joint name="joint5" type="hinge" axis="0 0 -1" pos="0 0 0"
                                           range="-1.57 1.57"/>
                                    <geom name="link5_visual" class="visual" mesh="link5" rgba="1 1 1 1" group="1"/>
                                    <geom name="link5_collision" class="collision" mesh="link5"/>
                                    <body name="link6" pos="0.0825 -0.0010782 -0.023822" euler="-1.5708 1.5708 0">
                                        <inertial pos="-0.0068528 -3.9973E-06 0.039705" mass="0.077892"
                                                  fullinertia="3.8236E-05 1.7707E-05 4.8839E-05 1.3465E-08 -2.0614E-07 -6.7117E-10"/>
                                        <joint name="joint6" type="hinge" axis="0 0 -1" pos="0 0 0"
                                               range="-2.35 2.35"/>
                                        <!-- <geom name="link6_visual" class="visual" mesh="link6" rgba="1 1 1 1" group="1"/>
                                        <geom name="link6_collision" class="collision" mesh="link6"/>  -->
                                        <!-- <body name="link7_1" pos="-0.0056388 -0.05164 0.0706" euler="1.5708 -3.14 1.5708">
                                            <inertial pos="0.018927 0.006 0.012082" mass="0.015046" fullinertia="1.2692E-06 2.0229E-06 2.6177E-06 7.7441E-20 -1.133E-07 1.2044E-20" />
                                            <joint name="joint7_1" type="slide" axis="0 0 1" pos="0 0 0" range="0 0.03" />
                                            <geom class="visual" mesh="link7_1" rgba="1 1 1 1" group="1"/>
                                            <geom class="collision" mesh="link7_1" />
                                            <body name="link7_2" pos="-0.0056388 0.05164 0.0706" euler="1.5708 0 1.5708">
                                                <inertial pos="0.018927 -0.006 0.012082" mass="0.015046" fullinertia="1.2692E-06 2.0229E-06 2.6177E-06 -7.8273E-20 -1.133E-07 -1.2122E-20" />
                                                <joint name="joint7_2" type="slide" axis="0 0 -1" pos="0 0 0" range="-0.03 0" />
                                                <geom class="visual" mesh="link7_2" rgba="1 1 1 1" group="1"/>
                                                <geom class="collision" mesh="link7_2" /> -->
                                                <!-- Replace gripper bodies with a dummy right_hand body -->
                                                
                                                <!-- </body>
                                            </body> -->
                                        <body name="right_hand" pos="0 0 0" quat="1 0 0 0">
                                            <camera mode="fixed" name="eye_in_hand" pos="0.05 0 0" quat="0 0.707108 0.707108 0" fovy="75"/>   
                                        </body>
                                    </body>
                                </body>
                            </body>
                        </body>
                    </body>
                </body>
            </body>
        </body>
    </worldbody>
    <default>
        <joint armature="1" damping="1" limited="true" name="default_joint"/>
        <default class="visual" name="default_visual">
            <geom type="mesh" contype="0" conaffinity="0" group="1"/>
        </default>
        <default class="collision" name="default_collision">
            <geom type="mesh" group="0"/>
        </default>
        <motor ctrlrange="-1 1" ctrllimited="true" name="default_motor"/>
    </default>
</mujoco>
